wer setting
found set_callback at <deccom.protocols.streamprotocol.StreamProtocol object at 0x000002AAB0D23BB0>
found set_stream_callback at <deccom.protocols.streamprotocol.StreamProtocol object at 0x000002AAB0D23BB0>
found set_connected_callback at <deccom.protocols.streamprotocol.StreamProtocol object at 0x000002AAB0D23BB0>
Node listening on 127.0.0.1:61569
TCP 61570
1 b'k\x86\xb2s\xff4\xfc\xe1\x9dk\x80N\xffZ?WG\xad\xa4\xea\xa2/\x1dI\xc0\x1eR\xdd\xb7\x87[K'
run...
started
started
started
CONNECTION FROM PEER
('127.0.0.1', 61581)
('127.0.0.1', 61581)
('127.0.0.1', 10015)
('127.0.0.1', 61581)
CONNECTION FROM PEER
closing ('127.0.0.1', 61582) b'\xd4s^:&^\x16\xee\xe0?Yq\x8b\x9b]\x03\x01\x9c\x07\xd8\xb6\xc5\x1f\x90\xda:fn\xec\x13\xab5'
('127.0.0.1', 10015)
('127.0.0.1', 61581)
('127.0.0.1', 61581)
('127.0.0.1', 61581)
('127.0.0.1', 61581)
('127.0.0.1', 61605)
('127.0.0.1', 10015)
CONNECTION FROM PEER
Task exception was never retrieved
future: <Task finished name='Task-2471' coro=<StreamProtocol.process_data() done, defined at D:\Games\PyDec\DecCom-Python\deccom\protocols\streamprotocol.py:158> exception=RuntimeError('Expected 3D (unbatched) or 4D (batched) input to conv2d, but got input of size: [5020]')>
Traceback (most recent call last):
  File "D:\Games\PyDec\DecCom-Python\deccom\protocols\streamprotocol.py", line 160, in process_data
    self.stream_callback(data,node_id,addr)
  File "D:\Games\PyDec\DecCom-Python\swarmprotocol.py", line 248, in process_data
    ret = SwarmProtocol.train(self.net,self.optimizer, inp_batch=data, rank = self.rank, stage = 1)
  File "D:\Games\PyDec\DecCom-Python\swarmprotocol.py", line 329, in train
    return net(inp_batch)
  File "D:\Games\pythonp\lib\site-packages\torch\nn\modules\module.py", line 1501, in _call_impl
    return forward_call(*args, **kwargs)
  File "D:\Games\PyDec\DecCom-Python\swarmtrainer.py", line 68, in forward
    x = F.relu(F.max_pool2d(self.conv2(x), 2))
  File "D:\Games\pythonp\lib\site-packages\torch\nn\modules\module.py", line 1501, in _call_impl
    return forward_call(*args, **kwargs)
  File "D:\Games\pythonp\lib\site-packages\torch\nn\modules\conv.py", line 463, in forward
    return self._conv_forward(input, self.weight, self.bias)
  File "D:\Games\pythonp\lib\site-packages\torch\nn\modules\conv.py", line 459, in _conv_forward
    return F.conv2d(input, weight, bias, self.stride,
RuntimeError: Expected 3D (unbatched) or 4D (batched) input to conv2d, but got input of size: [5020]
closing None b'K"ww\xd4\xdd\x1f\xc6\x1co\x88OHd\x1d\x02\xb4\xd1!\xd3\xfd2\x8c\xb0\x8bU1\xfc\xac\xda\xbf\x8a'
CONNECTION FROM PEER
CONNECTION FROM PEER
CONNECTION FROM PEER
CONNECTION FROM PEER
duplicate connection RECEIVED
-1 1
closing previous, keeping new
CONNECTION FROM PEER