Traceback (most recent call last):
  File "D:\Games\PyDec\DecCom-Python\deccom\protocols\defaultprotocol.py", line 51, in call_callback
    self.callback(addr,data)
  File "D:\Games\PyDec\DecCom-Python\deccom\protocols\peerdiscovery\kademliadiscovery.py", line 191, in process_datagram
    msg += self.finders[unique_id].look_for
KeyError: b'X\x9c\x18\xd2`^\x1f~'
Traceback (most recent call last):
  File "D:\Games\PyDec\DecCom-Python\deccom\protocols\defaultprotocol.py", line 51, in call_callback
    self.callback(addr,data)
  File "D:\Games\PyDec\DecCom-Python\deccom\protocols\peerdiscovery\kademliadiscovery.py", line 191, in process_datagram
    msg += self.finders[unique_id].look_for
KeyError: b'{\x0e\x9e\xe1\xf0nU\xbe'
Traceback (most recent call last):
  File "D:\Games\PyDec\DecCom-Python\deccom\protocols\defaultprotocol.py", line 51, in call_callback
    self.callback(addr,data)
  File "D:\Games\PyDec\DecCom-Python\deccom\protocols\peerdiscovery\kademliadiscovery.py", line 191, in process_datagram
    msg += self.finders[unique_id].look_for
KeyError: b'X\x9c\x18\xd2`^\x1f~'
Traceback (most recent call last):
  File "D:\Games\PyDec\DecCom-Python\deccom\protocols\defaultprotocol.py", line 51, in call_callback
    self.callback(addr,data)
  File "D:\Games\PyDec\DecCom-Python\deccom\protocols\peerdiscovery\kademliadiscovery.py", line 191, in process_datagram
    msg += self.finders[unique_id].look_for
KeyError: b'X\x9c\x18\xd2`^\x1f~'
Traceback (most recent call last):
  File "D:\Games\PyDec\DecCom-Python\deccom\protocols\defaultprotocol.py", line 51, in call_callback
    self.callback(addr,data)
  File "D:\Games\PyDec\DecCom-Python\deccom\protocols\peerdiscovery\kademliadiscovery.py", line 191, in process_datagram
    msg += self.finders[unique_id].look_for
KeyError: b'X\x9c\x18\xd2`^\x1f~'
Traceback (most recent call last):
  File "D:\Games\PyDec\DecCom-Python\deccom\protocols\defaultprotocol.py", line 51, in call_callback
    self.callback(addr,data)
  File "D:\Games\PyDec\DecCom-Python\deccom\protocols\peerdiscovery\kademliadiscovery.py", line 191, in process_datagram
    msg += self.finders[unique_id].look_for
KeyError: b'X\x9c\x18\xd2`^\x1f~'
